<?xml version="1.0" ?>
<sdf version="1.6">
  <model name="barrage">
    

    <link name="attachment_link">
      <pose>0 0 0 0 0 1.51</pose>
    </link>

    <link name="attachment_link_2">
      <pose>3.8 0 0 0 0 1.51</pose>
    </link>

    <include>
      <pose>0 0 0 0 0 0</pose>
      <uri>model://barrage_buoy</uri>
      <name>sphere1</name>
    </include>

    <include>
      <pose>0.4 0 0 0 0 0</pose>
      <uri>model://barrage_buoy</uri>
      <name>sphere2</name>
    </include>

    <include>
      <pose>0.8 0 0 0 0 0</pose>
      <uri>model://barrage_buoy</uri>
      <name>sphere3</name>
    </include>

    <include>
      <pose>1.2 0 0 0 0 0</pose>
      <uri>model://barrage_buoy</uri>
      <name>sphere4</name>
    </include>


    <include>
      <pose>1.6 0 0 0 0 0</pose>
      <uri>model://barrage_buoy</uri>
      <name>sphere5</name>
    </include>


    <include>
      <pose>2.0 0 0 0 0 0</pose>
      <uri>model://barrage_buoy</uri>
      <name>sphere6</name>
    </include>


    <include>
      <pose>2.4 0 0 0 0 0</pose>
      <uri>model://barrage_buoy</uri>
      <name>sphere7</name>
    </include>


    <include>
      <pose>2.8 0 0 0 0 0</pose>
      <uri>model://barrage_buoy</uri>
      <name>sphere8</name>
    </include>


    <include>
      <pose>3.2 0 0 0 0 0</pose>
      <uri>model://barrage_buoy</uri>
      <name>sphere9</name>
    </include>


    <include>
      <pose>3.6 0 0 0 0 0</pose>
      <uri>model://barrage_buoy</uri>
      <name>sphere10</name>
    </include>



    <joint name="joint1" type="universal">
      <parent>sphere1</parent>
      <child>sphere2</child>
      <axis>
        <xyz>0 1 0</xyz>
        <limit>
          <lower>-0.05</lower>
          <upper>0.05</upper>
        </limit>
      </axis>
      <axis2>
        <xyz>1 0 0</xyz>
        <limit>
          <lower>-0.05</lower>
          <upper>0.05</upper>
        </limit>
      </axis2>
      <pose>0.2 0 0 0 0 0</pose>
    </joint>

    <joint name="joint2" type="universal">
      <parent>sphere2</parent>
      <child>sphere3</child>
      <axis>
        <xyz>0 1 0</xyz>
        <limit>
          <lower>-0.05</lower>
          <upper>0.05</upper>
        </limit>
      </axis>
      <axis2>
        <xyz>1 0 0</xyz>
        <limit>
          <lower>-0.05</lower>
          <upper>0.05</upper>
        </limit>
      </axis2>
      <pose>0.6 0 0 0 0 0</pose>
    </joint>


    <joint name="joint3" type="universal">
      <parent>sphere3</parent>
      <child>sphere4</child>
      <axis>
        <xyz>0 1 0</xyz>
        <limit>
          <lower>-0.05</lower>
          <upper>0.05</upper>
        </limit>
      </axis>
      <axis2>
        <xyz>1 0 0</xyz>
        <limit>
          <lower>-0.05</lower>
          <upper>0.05</upper>
        </limit>
      </axis2>
      <pose>1.0 0 0 0 0 0</pose>
    </joint>


    <joint name="joint4" type="universal">
      <parent>sphere4</parent>
      <child>sphere5</child>
      <axis>
        <xyz>0 1 0</xyz>
        <limit>
          <lower>-0.05</lower>
          <upper>0.05</upper>
        </limit>
      </axis>
      <axis2>
        <xyz>1 0 0</xyz>
        <limit>
          <lower>-0.05</lower>
          <upper>0.05</upper>
        </limit>
      </axis2>
      <pose>1.4 0 0 0 0 0</pose>
    </joint>


    <joint name="joint5" type="universal">
      <parent>sphere5</parent>
      <child>sphere6</child>
      <axis>
        <xyz>0 1 0</xyz>
        <limit>
          <lower>-0.05</lower>
          <upper>0.05</upper>
        </limit>
      </axis>
      <axis2>
        <xyz>1 0 0</xyz>
        <limit>
          <lower>-0.05</lower>
          <upper>0.05</upper>
        </limit>
      </axis2>
      <pose>1.8 0 0 0 0 0</pose>
    </joint>


    <joint name="joint6" type="universal">
      <parent>sphere6</parent>
      <child>sphere7</child>
      <axis>
        <xyz>0 1 0</xyz>
        <limit>
          <lower>-0.05</lower>
          <upper>0.05</upper>
        </limit>
      </axis>
      <axis2>
        <xyz>1 0 0</xyz>
        <limit>
          <lower>-0.05</lower>
          <upper>0.05</upper>
        </limit>
      </axis2>
      <pose>2.2 0 0 0 0 0</pose>
    </joint>


    <joint name="joint7" type="universal">
      <parent>sphere7</parent>
      <child>sphere8</child>
      <axis>
        <xyz>0 1 0</xyz>
        <limit>
          <lower>-0.05</lower>
          <upper>0.05</upper>
        </limit>
      </axis>
      <axis2>
        <xyz>1 0 0</xyz>
        <limit>
          <lower>-0.05</lower>
          <upper>0.05</upper>
        </limit>
      </axis2>
      <pose>2.6 0 0 0 0 0</pose>
    </joint>


    <joint name="joint8" type="universal">
      <parent>sphere8</parent>
      <child>sphere9</child>
      <axis>
        <xyz>0 1 0</xyz>
        <limit>
          <lower>-0.05</lower>
          <upper>0.05</upper>
        </limit>
      </axis>
      <axis2>
        <xyz>1 0 0</xyz>
        <limit>
          <lower>-0.05</lower>
          <upper>0.05</upper>
        </limit>
      </axis2>
      <pose>3.0 0 0 0 0 0</pose>
    </joint>


    <joint name="joint9" type="universal">
      <parent>sphere9</parent>
      <child>sphere10</child>
      <axis>
        <xyz>0 1 0</xyz>
        <limit>
          <lower>-0.05</lower>
          <upper>0.05</upper>
        </limit>
      </axis>
      <axis2>
        <xyz>1 0 0</xyz>
        <limit>
          <lower>-0.05</lower>
          <upper>0.05</upper>
        </limit>
      </axis2>
      <pose>3.4 0 0 0 0 0</pose>
    </joint>

  </model>
</sdf>
