<?xml version="1.0" ?>
<sdf version="1.6">
  <world name="waves">
    <plugin filename="gz-sim-physics-system"
            name="gz::sim::systems::Physics">
    </plugin>
    <plugin filename="gz-sim-sensors-system"
            name="gz::sim::systems::Sensors">
      <render_engine>ogre2</render_engine>
      <background_color>0.8 0.8 0.8</background_color>
    </plugin>
    <plugin filename="gz-sim-scene-broadcaster-system"
            name="gz::sim::systems::SceneBroadcaster">
    </plugin>
    <plugin filename="gz-sim-user-commands-system"
            name="gz::sim::systems::UserCommands">
    </plugin>
    <plugin filename="gz-sim-imu-system"
            name="gz::sim::systems::Imu">
    </plugin>

    <!-- Processes the NavSat sensor -->
    <plugin
      filename="gz-sim-navsat-system"
      name="gz::sim::systems::NavSat">
    </plugin>

    <!-- Set the coordinates for the world origin -->
    <spherical_coordinates>
      <surface_model>EARTH_WGS84</surface_model>
      <world_frame_orientation>ENU</world_frame_orientation>
      <latitude_deg>-22.986687</latitude_deg>
      <longitude_deg>-43.202501</longitude_deg>
      <elevation>0</elevation>
      <heading_deg>0</heading_deg>
    </spherical_coordinates>

    <scene>
      <ambient>1.0 1.0 1.0</ambient>
      <background>0.8 0.8 0.8</background>
      <sky></sky>
    </scene>

    <light type="directional" name="sun">
      <cast_shadows>true</cast_shadows>
      <pose>0 0 10 0 0 0</pose>
      <diffuse>0.8 0.8 0.8 1</diffuse>
      <specular>0.6 0.6 0.6 1</specular>
      <direction>-0.5 0.1 -0.9</direction>
    </light>

<!-- <physics type="ode">
  <max_step_size>0.002</max_step_size>
  <real_time_factor>1.0</real_time_factor>
  <real_time_update_rate>500</real_time_update_rate>
</physics> -->

<!-- <physics type="ode">
  <max_step_size>0.004</max_step_size>
  <real_time_factor>1.0</real_time_factor>
  <real_time_update_rate>1000</real_time_update_rate>
</physics> -->

    <include>
      <pose>0 0 0 0 0 0</pose>
      <uri>model://waves</uri>
    </include>

    <include>
      <pose>1.3 0 -3 0 0 0</pose>
      <uri>model://wavetank</uri>
    </include>

    <include>
      <pose>4 2 -3 0 0 0</pose>
      <uri>model://obstacle</uri>
    </include>




    <!-- <include>
      <pose>5 0 -6 0 0 0</pose>
      <uri>model://wind_turbine</uri>
    </include> -->

    <!-- <include>
      <pose>12 0 -6 0 0 0</pose>
      <uri>model://bop_panel</uri>
    </include> -->

    <!-- Define global parameters -->
    <xacro:property name="joint_limit_lower" value="-1.5" />
    <xacro:property name="joint_limit_upper" value="1.5" />
    <xacro:property name="joint_damping" value="0.05" />

    <!-- Include the BlueBoat -->
    <include>
      <pose>0 0 0 0 0 0</pose>
      <uri>model://blueboat</uri>
    </include>

    <!-- Include barrage buoys to extend the cable length to 3 meters -->

    <!-- Include the first Barrage Buoy -->
    <include>
      <pose>-0.5 0 0 0 0 0</pose>
      <uri>model://barrage_buoy3</uri>
      <name>barrage_buoy_1</name>
    </include>

    <joint name="blueboat_to_barragebuoy1_joint" type="ball">
      <parent>blueboat::base_link</parent>
      <child>barrage_buoy_1::base_link</child>
      <pose>0 0 0 0 0 0</pose>
      <physics>
        <limit>
          <lower>${joint_limit_lower}</lower>
          <upper>${joint_limit_upper}</upper>
        </limit>
        <dynamics>
          <damping>${joint_damping}</damping>
        </dynamics>
      </physics>
    </joint>

    <!-- Barrage Buoy 2 -->
    <include>
      <pose>-1.0 0 0 0 0 0</pose>
      <uri>model://barrage_buoy3</uri>
      <name>barrage_buoy_2</name>
    </include>

    <joint name="barragebuoy1_to_barragebuoy2_joint" type="ball">
      <parent>barrage_buoy_1::base_link</parent>
      <child>barrage_buoy_2::base_link</child>
      <pose>0 0 0 0 0 0</pose>
      <physics>
        <limit>
          <lower>${joint_limit_lower}</lower>
          <upper>${joint_limit_upper}</upper>
        </limit>
        <dynamics>
          <damping>${joint_damping}</damping>
        </dynamics>
      </physics>
    </joint>

    <!-- Barrage Buoy 3 -->
    <include>
      <pose>-1.5 0 0 0 0 0</pose>
      <uri>model://barrage_buoy3</uri>
      <name>barrage_buoy_3</name>
    </include>

    <joint name="barragebuoy2_to_barragebuoy3_joint" type="ball">
      <parent>barrage_buoy_2::base_link</parent>
      <child>barrage_buoy_3::base_link</child>
      <pose>0 0 0 0 0 0</pose>
      <physics>
        <limit>
          <lower>${joint_limit_lower}</lower>
          <upper>${joint_limit_upper}</upper>
        </limit>
        <dynamics>
          <damping>${joint_damping}</damping>
        </dynamics>
      </physics>
    </joint>

    <!-- Barrage Buoy 4 -->
    <include>
      <pose>-2.0 0 0 0 0 0</pose>
      <uri>model://barrage_buoy3</uri>
      <name>barrage_buoy_4</name>
    </include>

    <joint name="barragebuoy3_to_barragebuoy4_joint" type="ball">
      <parent>barrage_buoy_3::base_link</parent>
      <child>barrage_buoy_4::base_link</child>
      <pose>0 0 0 0 0 0</pose>
      <physics>
        <limit>
          <lower>${joint_limit_lower}</lower>
          <upper>${joint_limit_upper}</upper>
        </limit>
        <dynamics>
          <damping>${joint_damping}</damping>
        </dynamics>
      </physics>
    </joint>

    <!-- Barrage Buoy 5 -->
    <include>
      <pose>-2.5 0 0 0 0 0</pose>
      <uri>model://barrage_buoy3</uri>
      <name>barrage_buoy_5</name>
    </include>

    <joint name="barragebuoy4_to_barragebuoy5_joint" type="ball">
      <parent>barrage_buoy_4::base_link</parent>
      <child>barrage_buoy_5::base_link</child>
      <pose>0 0 0 0 0 0</pose>
      <physics>
        <limit>
          <lower>${joint_limit_lower}</lower>
          <upper>${joint_limit_upper}</upper>
        </limit>
        <dynamics>
          <damping>${joint_damping}</damping>
        </dynamics>
      </physics>
    </joint>

    <!-- Barrage Buoy 6 -->
    <include>
      <pose>-3.0 0 0 0 0 0</pose>
      <uri>model://barrage_buoy3</uri>
      <name>barrage_buoy_6</name>
    </include>

    <joint name="barragebuoy5_to_barragebuoy6_joint" type="ball">
      <parent>barrage_buoy_5::base_link</parent>
      <child>barrage_buoy_6::base_link</child>
      <pose>0 0 0 0 0 0</pose>
      <physics>
        <limit>
          <lower>${joint_limit_lower}</lower>
          <upper>${joint_limit_upper}</upper>
        </limit>
        <dynamics>
          <damping>${joint_damping}</damping>
        </dynamics>
      </physics>
    </joint>

    <!-- Include the BlueROV2 at the end of the 3-meter length -->
    <include>
      <pose>-3.5 0 -0.3 0 0 0</pose>
      <uri>model://bluerov2_heavy</uri>
      <name>bluerov2_heavy</name>
    </include>

    <!-- Ball Joint connecting the last Barrage Buoy to BlueROV2 -->
    <joint name="barragebuoy6_to_bluerov2_joint" type="ball">
      <parent>barrage_buoy_6::base_link</parent>
      <child>bluerov2_heavy::base_link</child>
      <pose>0 0 0 0 0 0</pose>
      <physics>
        <limit>
          <lower>${joint_limit_lower}</lower>
          <upper>${joint_limit_upper}</upper>
        </limit>
        <dynamics>
          <damping>${joint_damping}</damping>
        </dynamics>
      </physics>
    </joint>

  </world>
</sdf>
