<?xml version="1.0" ?>
<sdf version="1.6">
  <world name="waves">
    <plugin filename="gz-sim-physics-system"
            name="gz::sim::systems::Physics">
    </plugin>
    <plugin filename="gz-sim-sensors-system"
            name="gz::sim::systems::Sensors">
      <render_engine>ogre2</render_engine>
      <background_color>0.8 0.8 0.8</background_color>
    </plugin>
    <plugin filename="gz-sim-scene-broadcaster-system"
            name="gz::sim::systems::SceneBroadcaster">
    </plugin>
    <plugin filename="gz-sim-user-commands-system"
            name="gz::sim::systems::UserCommands">
    </plugin>
    <plugin filename="gz-sim-imu-system"
            name="gz::sim::systems::Imu">
    </plugin>


    <plugin
      filename="gz-sim-buoyancy-system"
      name="gz::sim::systems::Buoyancy">
      <graded_buoyancy>
        <default_density>1025</default_density>
        <density_change>
          <above_depth>0</above_depth>
          <density>1.125</density>
        </density_change>
      </graded_buoyancy>
    </plugin>

    <!-- Processes the NavSat sensor -->
    <plugin
      filename="gz-sim-navsat-system"
      name="gz::sim::systems::NavSat">
    </plugin>

    <!-- Set the coordinates for the world origin -->
    <spherical_coordinates>
      <surface_model>EARTH_WGS84</surface_model>
      <world_frame_orientation>ENU</world_frame_orientation>
      <latitude_deg>-22.986687</latitude_deg>
      <longitude_deg>-43.202501</longitude_deg>
      <elevation>0</elevation>
      <heading_deg>0</heading_deg>
    </spherical_coordinates>

    <scene>
      <ambient>1.0 1.0 1.0</ambient>
      <background>0.8 0.8 0.8</background>
      <sky></sky>
    </scene>

    <light type="directional" name="sun">
      <cast_shadows>true</cast_shadows>
      <pose>0 0 10 0 0 0</pose>
      <diffuse>0.8 0.8 0.8 1</diffuse>
      <specular>0.6 0.6 0.6 1</specular>
      <direction>-0.5 0.1 -0.9</direction>
    </light>

    <include>
      <pose>0 0 0 0 0 0</pose>
      <uri>model://waves</uri>
    </include>

    <include>
      <pose>5 0 -6 0 0 0</pose>
      <uri>model://wind_turbine</uri>
    </include>

    <include>
      <pose>12 0 -6 0 0 0</pose>
      <uri>model://bop_panel</uri>
    </include>

    <!-- Define global parameters -->
    <xacro:property name="joint_limit_lower" value="-1.5" />
    <xacro:property name="joint_limit_upper" value="1.5" />
    <xacro:property name="joint_damping" value="0.05" />

    <!-- Include the BlueBoat -->
    <include>
      <pose>0 0 0 0 0 0</pose>
      <uri>model://blueboat</uri>
    </include>

    <!-- Include barrage buoys to extend the cable length to 10 meters -->
    <!-- Include the first Barrage Buoy -->
    <include>
      <pose>-0.5 0 0 0 0 0</pose>
      <uri>model://barrage_buoy10</uri>
      <name>barrage_buoy_1</name>
    </include>

    <joint name="blueboat_to_barragebuoy1_joint" type="ball">
      <parent>blueboat::base_link</parent>
      <child>barrage_buoy_1::base_link</child>
      <pose>0 0 0 0 0 0</pose>
      <physics>
        <limit>
          <lower>${joint_limit_lower}</lower>
          <upper>${joint_limit_upper}</upper>
        </limit>
        <dynamics>
          <damping>${joint_damping}</damping>
        </dynamics>
      </physics>
    </joint>

    <!-- Add additional barrage buoys to reach a total distance of 10 meters -->

    <!-- Barrage Buoy 2 -->
    <include>
      <pose>-1.0 0 0 0 0 0</pose>
      <uri>model://barrage_buoy10</uri>
      <name>barrage_buoy_2</name>
    </include>

    <joint name="barragebuoy1_to_barragebuoy2_joint" type="ball">
      <parent>barrage_buoy_1::base_link</parent>
      <child>barrage_buoy_2::base_link</child>
      <pose>0 0 0 0 0 0</pose>
      <physics>
        <limit>
          <lower>${joint_limit_lower}</lower>
          <upper>${joint_limit_upper}</upper>
        </limit>
        <dynamics>
          <damping>${joint_damping}</damping>
        </dynamics>
      </physics>
    </joint>

    <!-- Barrage Buoy 3 -->
    <include>
      <pose>-1.5 0 0 0 0 0</pose>
      <uri>model://barrage_buoy10</uri>
      <name>barrage_buoy_3</name>
    </include>

    <joint name="barragebuoy2_to_barragebuoy3_joint" type="ball">
      <parent>barrage_buoy_2::base_link</parent>
      <child>barrage_buoy_3::base_link</child>
      <pose>0 0 0 0 0 0</pose>
      <physics>
        <limit>
          <lower>${joint_limit_lower}</lower>
          <upper>${joint_limit_upper}</upper>
        </limit>
        <dynamics>
          <damping>${joint_damping}</damping>
        </dynamics>
      </physics>
    </joint>

    <!-- Barrage Buoy 4 -->
    <include>
      <pose>-2.0 0 0 0 0 0</pose>
      <uri>model://barrage_buoy10</uri>
      <name>barrage_buoy_4</name>
    </include>

    <joint name="barragebuoy3_to_barragebuoy4_joint" type="ball">
      <parent>barrage_buoy_3::base_link</parent>
      <child>barrage_buoy_4::base_link</child>
      <pose>0 0 0 0 0 0</pose>
      <physics>
        <limit>
          <lower>${joint_limit_lower}</lower>
          <upper>${joint_limit_upper}</upper>
        </limit>
        <dynamics>
          <damping>${joint_damping}</damping>
        </dynamics>
      </physics>
    </joint>

    <!-- Barrage Buoy 5 -->
    <include>
      <pose>-2.5 0 0 0 0 0</pose>
      <uri>model://barrage_buoy10</uri>
      <name>barrage_buoy_5</name>
    </include>

    <joint name="barragebuoy4_to_barragebuoy5_joint" type="ball">
      <parent>barrage_buoy_4::base_link</parent>
      <child>barrage_buoy_5::base_link</child>
      <pose>0 0 0 0 0 0</pose>
      <physics>
        <limit>
          <lower>${joint_limit_lower}</lower>
          <upper>${joint_limit_upper}</upper>
        </limit>
        <dynamics>
          <damping>${joint_damping}</damping>
        </dynamics>
      </physics>
    </joint>

    <!-- Barrage Buoy 6 -->
    <include>
      <pose>-3.0 0 0 0 0 0</pose>
      <uri>model://barrage_buoy10</uri>
      <name>barrage_buoy_6</name>
    </include>

    <joint name="barragebuoy5_to_barragebuoy6_joint" type="ball">
      <parent>barrage_buoy_5::base_link</parent>
      <child>barrage_buoy_6::base_link</child>
      <pose>0 0 0 0 0 0</pose>
      <physics>
        <limit>
          <lower>${joint_limit_lower}</lower>
          <upper>${joint_limit_upper}</upper>
        </limit>
        <dynamics>
          <damping>${joint_damping}</damping>
        </dynamics>
      </physics>
    </joint>

    <!-- Barrage Buoy 7 -->
    <include>
      <pose>-3.5 0 0 0 0 0</pose>
      <uri>model://barrage_buoy10</uri>
      <name>barrage_buoy_7</name>
    </include>

    <joint name="barragebuoy6_to_barragebuoy7_joint" type="ball">
      <parent>barrage_buoy_6::base_link</parent>
      <child>barrage_buoy_7::base_link</child>
      <pose>0 0 0 0 0 0</pose>
      <physics>
        <limit>
          <lower>${joint_limit_lower}</lower>
          <upper>${joint_limit_upper}</upper>
        </limit>
        <dynamics>
          <damping>${joint_damping}</damping>
        </dynamics>
      </physics>
    </joint>

    <!-- Barrage Buoy 8 -->
    <include>
      <pose>-4.0 0 0 0 0 0</pose>
      <uri>model://barrage_buoy10</uri>
      <name>barrage_buoy_8</name>
    </include>

    <joint name="barragebuoy7_to_barragebuoy8_joint" type="ball">
      <parent>barrage_buoy_7::base_link</parent>
      <child>barrage_buoy_8::base_link</child>
      <pose>0 0 0 0 0 0</pose>
      <physics>
        <limit>
          <lower>${joint_limit_lower}</lower>
          <upper>${joint_limit_upper}</upper>
        </limit>
        <dynamics>
          <damping>${joint_damping}</damping>
        </dynamics>
      </physics>
    </joint>

    <!-- Barrage Buoy 9 -->
    <include>
      <pose>-4.5 0 0 0 0 0</pose>
      <uri>model://barrage_buoy10</uri>
      <name>barrage_buoy_9</name>
    </include>

    <joint name="barragebuoy8_to_barragebuoy9_joint" type="ball">
      <parent>barrage_buoy_8::base_link</parent>
      <child>barrage_buoy_9::base_link</child>
      <pose>0 0 0 0 0 0</pose>
      <physics>
        <limit>
          <lower>${joint_limit_lower}</lower>
          <upper>${joint_limit_upper}</upper>
        </limit>
        <dynamics>
          <damping>${joint_damping}</damping>
        </dynamics>
      </physics>
    </joint>

    <!-- Barrage Buoy 10 -->
    <include>
      <pose>-5.0 0 0 0 0 0</pose>
      <uri>model://barrage_buoy10</uri>
      <name>barrage_buoy_10</name>
    </include>

    <joint name="barragebuoy9_to_barragebuoy10_joint" type="ball">
      <parent>barrage_buoy_9::base_link</parent>
      <child>barrage_buoy_10::base_link</child>
      <pose>0 0 0 0 0 0</pose>
      <physics>
        <limit>
          <lower>${joint_limit_lower}</lower>
          <upper>${joint_limit_upper}</upper>
        </limit>
        <dynamics>
          <damping>${joint_damping}</damping>
        </dynamics>
      </physics>
    </joint>

    <!-- Continue adding more buoys up to the 10-meter length -->

    <!-- Barrage Buoy 11 -->
    <include>
      <pose>-5.5 0 0 0 0 0</pose>
      <uri>model://barrage_buoy10</uri>
      <name>barrage_buoy_11</name>
    </include>

    <joint name="barragebuoy10_to_barragebuoy11_joint" type="ball">
      <parent>barrage_buoy_10::base_link</parent>
      <child>barrage_buoy_11::base_link</child>
      <pose>0 0 0 0 0 0</pose>
      <physics>
        <limit>
          <lower>${joint_limit_lower}</lower>
          <upper>${joint_limit_upper}</upper>
        </limit>
        <dynamics>
          <damping>${joint_damping}</damping>
        </dynamics>
      </physics>
    </joint>

    <!-- Barrage Buoy 12 -->
    <include>
      <pose>-6.0 0 0 0 0 0</pose>
      <uri>model://barrage_buoy10</uri>
      <name>barrage_buoy_12</name>
    </include>

    <joint name="barragebuoy11_to_barragebuoy12_joint" type="ball">
      <parent>barrage_buoy_11::base_link</parent>
      <child>barrage_buoy_12::base_link</child>
      <pose>0 0 0 0 0 0</pose>
      <physics>
        <limit>
          <lower>${joint_limit_lower}</lower>
          <upper>${joint_limit_upper}</upper>
        </limit>
        <dynamics>
          <damping>${joint_damping}</damping>
        </dynamics>
      </physics>
    </joint>

    <!-- Barrage Buoy 13 -->
    <include>
      <pose>-6.5 0 0 0 0 0</pose>
      <uri>model://barrage_buoy10</uri>
      <name>barrage_buoy_13</name>
    </include>

    <joint name="barragebuoy12_to_barragebuoy13_joint" type="ball">
      <parent>barrage_buoy_12::base_link</parent>
      <child>barrage_buoy_13::base_link</child>
      <pose>0 0 0 0 0 0</pose>
      <physics>
        <limit>
          <lower>${joint_limit_lower}</lower>
          <upper>${joint_limit_upper}</upper>
        </limit>
        <dynamics>
          <damping>${joint_damping}</damping>
        </dynamics>
      </physics>
    </joint>

    <!-- Barrage Buoy 14 -->
    <include>
      <pose>-7.0 0 0 0 0 0</pose>
      <uri>model://barrage_buoy10</uri>
      <name>barrage_buoy_14</name>
    </include>

    <joint name="barragebuoy13_to_barragebuoy14_joint" type="ball">
      <parent>barrage_buoy_13::base_link</parent>
      <child>barrage_buoy_14::base_link</child>
      <pose>0 0 0 0 0 0</pose>
      <physics>
        <limit>
          <lower>${joint_limit_lower}</lower>
          <upper>${joint_limit_upper}</upper>
        </limit>
        <dynamics>
          <damping>${joint_damping}</damping>
        </dynamics>
      </physics>
    </joint>

    <!-- Barrage Buoy 15 -->
    <include>
      <pose>-7.5 0 0 0 0 0</pose>
      <uri>model://barrage_buoy10</uri>
      <name>barrage_buoy_15</name>
    </include>

    <joint name="barragebuoy14_to_barragebuoy15_joint" type="ball">
      <parent>barrage_buoy_14::base_link</parent>
      <child>barrage_buoy_15::base_link</child>
      <pose>0 0 0 0 0 0</pose>
      <physics>
        <limit>
          <lower>${joint_limit_lower}</lower>
          <upper>${joint_limit_upper}</upper>
        </limit>
        <dynamics>
          <damping>${joint_damping}</damping>
        </dynamics>
      </physics>
    </joint>

    <!-- Barrage Buoy 16 -->
    <include>
      <pose>-8.0 0 0 0 0 0</pose>
      <uri>model://barrage_buoy10</uri>
      <name>barrage_buoy_16</name>
    </include>

    <joint name="barragebuoy15_to_barragebuoy16_joint" type="ball">
      <parent>barrage_buoy_15::base_link</parent>
      <child>barrage_buoy_16::base_link</child>
      <pose>0 0 0 0 0 0</pose>
      <physics>
        <limit>
          <lower>${joint_limit_lower}</lower>
          <upper>${joint_limit_upper}</upper>
        </limit>
        <dynamics>
          <damping>${joint_damping}</damping>
        </dynamics>
      </physics>
    </joint>

    <!-- Barrage Buoy 17 -->
    <include>
      <pose>-8.5 0 0 0 0 0</pose>
      <uri>model://barrage_buoy10</uri>
      <name>barrage_buoy_17</name>
    </include>

    <joint name="barragebuoy16_to_barragebuoy17_joint" type="ball">
      <parent>barrage_buoy_16::base_link</parent>
      <child>barrage_buoy_17::base_link</child>
      <pose>0 0 0 0 0 0</pose>
      <physics>
        <limit>
          <lower>${joint_limit_lower}</lower>
          <upper>${joint_limit_upper}</upper>
        </limit>
        <dynamics>
          <damping>${joint_damping}</damping>
        </dynamics>
      </physics>
    </joint>

    <!-- Barrage Buoy 18 -->
    <include>
      <pose>-9.0 0 0 0 0 0</pose>
      <uri>model://barrage_buoy10</uri>
      <name>barrage_buoy_18</name>
    </include>

    <joint name="barragebuoy17_to_barragebuoy18_joint" type="ball">
      <parent>barrage_buoy_17::base_link</parent>
      <child>barrage_buoy_18::base_link</child>
      <pose>0 0 0 0 0 0</pose>
      <physics>
        <limit>
          <lower>${joint_limit_lower}</lower>
          <upper>${joint_limit_upper}</upper>
        </limit>
        <dynamics>
          <damping>${joint_damping}</damping>
        </dynamics>
      </physics>
    </joint>

    <!-- Barrage Buoy 19 -->
    <include>
      <pose>-9.5 0 0 0 0 0</pose>
      <uri>model://barrage_buoy10</uri>
      <name>barrage_buoy_19</name>
    </include>

    <joint name="barragebuoy18_to_barragebuoy19_joint" type="ball">
      <parent>barrage_buoy_18::base_link</parent>
      <child>barrage_buoy_19::base_link</child>
      <pose>0 0 0 0 0 0</pose>
      <physics>
        <limit>
          <lower>${joint_limit_lower}</lower>
          <upper>${joint_limit_upper}</upper>
        </limit>
        <dynamics>
          <damping>${joint_damping}</damping>
        </dynamics>
      </physics>
    </joint>

    <!-- Barrage Buoy 20 -->
    <include>
      <pose>-10.0 0 0 0 0 0</pose>
      <uri>model://barrage_buoy10</uri>
      <name>barrage_buoy_20</name>
    </include>

    <joint name="barragebuoy19_to_barragebuoy20_joint" type="ball">
      <parent>barrage_buoy_19::base_link</parent>
      <child>barrage_buoy_20::base_link</child>
      <pose>0 0 0 0 0 0</pose>
      <physics>
        <limit>
          <lower>${joint_limit_lower}</lower>
          <upper>${joint_limit_upper}</upper>
        </limit>
        <dynamics>
          <damping>${joint_damping}</damping>
        </dynamics>
      </physics>
    </joint>

    <!-- Include the BlueROV2 at the end of the 10-meter length -->
    <include>
      <pose>-10.5 0 -0.3 0 0 0</pose>
      <uri>model://bluerov2_heavy</uri>
      <name>bluerov2_heavy</name>
    </include>

    <!-- Ball Joint connecting the last Barrage Buoy to BlueROV2 -->
    <joint name="barragebuoy20_to_bluerov2_joint" type="ball">
      <parent>barrage_buoy_20::base_link</parent>
      <child>bluerov2_heavy::base_link</child>
      <pose>0 0 0 0 0 0</pose>
      <physics>
        <limit>
          <lower>${joint_limit_lower}</lower>
          <upper>${joint_limit_upper}</upper>
        </limit>
        <dynamics>
          <damping>${joint_damping}</damping>
        </dynamics>
      </physics>
    </joint>

  </world>
</sdf>
