<?xml version="1.0" ?>
<sdf version="1.6">
  <world name="waves">
    <plugin filename="gz-sim-physics-system"
            name="gz::sim::systems::Physics">
    </plugin>
    <plugin filename="gz-sim-sensors-system"
            name="gz::sim::systems::Sensors">
      <render_engine>ogre2</render_engine>
      <background_color>0.8 0.8 0.8</background_color>
    </plugin>
    <plugin filename="gz-sim-scene-broadcaster-system"
            name="gz::sim::systems::SceneBroadcaster">
    </plugin>
    <plugin filename="gz-sim-user-commands-system"
            name="gz::sim::systems::UserCommands">
    </plugin>
    <plugin filename="gz-sim-imu-system"
            name="gz::sim::systems::Imu">
    </plugin>


    <!-- <plugin
      filename="gz-sim-buoyancy-system"
      name="gz::sim::systems::Buoyancy">
      <graded_buoyancy>
        <default_density>1000</default_density>
        <density_change>
          <above_depth>0</above_depth>
          <density>1</density>
        </density_change>
      </graded_buoyancy>
      <enable>bluerov2_heavy</enable>
    </plugin> -->



    <!-- Processes the NavSat sensor -->
    <plugin
      filename="gz-sim-navsat-system"
      name="gz::sim::systems::NavSat">
    </plugin>

        <!-- Set the coordinates for the world origin -->
    <spherical_coordinates>
      <surface_model>EARTH_WGS84</surface_model>
      <world_frame_orientation>ENU</world_frame_orientation>
      <latitude_deg>-22.986687</latitude_deg>
      <longitude_deg>-43.202501</longitude_deg>
      <elevation>0</elevation>
      <heading_deg>0</heading_deg>
    </spherical_coordinates>

    <scene>
      <ambient>1.0 1.0 1.0</ambient>
      <background>0.8 0.8 0.8</background>
      <sky></sky>
    </scene>

    <light type="directional" name="sun">
      <cast_shadows>true</cast_shadows>
      <pose>0 0 10 0 0 0</pose>
      <diffuse>0.8 0.8 0.8 1</diffuse>
      <specular>0.6 0.6 0.6 1</specular>
      <direction>-0.5 0.1 -0.9</direction>
    </light>

    <include>
      <pose>0 0 0 0 0 0</pose>
      <uri>model://waves</uri>
    </include>

    <!-- ENU axes -->
    <!-- <model name="axes">
      <static>1</static>
      <link name="link">
        <visual name="r">
          <cast_shadows>0</cast_shadows>
          <pose>5 0 0.1 0 0 0</pose>
          <geometry>
            <box>
              <size>10 0.01 0.01</size>
            </box>
          </geometry>
          <material>
            <ambient>1 0 0 1</ambient>
            <diffuse>1 0 0 1</diffuse>
            <emissive>1 0 0 1</emissive>
            <specular>0.5 0.5 0.5 1</specular>
          </material>
        </visual>
        <visual name="g">
          <cast_shadows>0</cast_shadows>
          <pose>0 5 0.1 0 0 0</pose>
          <geometry>
            <box>
              <size>0.01 10 0.01</size>
            </box>
          </geometry>
          <material>
            <ambient>0 1 0 1</ambient>
            <diffuse>0 1 0 1</diffuse>
            <emissive>0 1 0 1</emissive>
            <specular>0.5 0.5 0.5 1</specular>
          </material>
        </visual>
        <visual name="b">
          <cast_shadows>0</cast_shadows>
          <pose>0 0 5.1 0 0 0</pose>
          <geometry>
            <box>
              <size>0.01 0.01 10</size>
            </box>
          </geometry>
          <material>
            <ambient>0 0 1 1</ambient>
            <diffuse>0 0 1 1</diffuse>
            <emissive>0 0 1 1</emissive>
            <specular>0.5 0.5 0.5 1</specular>
          </material>
        </visual>
      </link>
    </model> -->


<!-- TODO -->
<!-- TODO -->
    <!-- <include>
      <pose>0 5 0 0 0 0</pose>
      <uri>model://spherical_buoy</uri>
    </include> -->
<!-- TODO -->
<!-- TODO -->


<!-- <include>
  <pose>0 0 0 0 0 3.1415</pose>
  <uri>model://barrage</uri>
</include> -->

  <!-- Joint connecting the BlueBoat to the Barrage -->
  <!-- <joint name="blueboat_to_barrage_joint" type="revolute">
    <parent>blueboat::base_link</parent> 
    <child>barrage::attachment_link</child> 
    <pose>0 0 0 0 0 0</pose> 
    <axis>
      <xyz>0 1 0</xyz>
      <limit>
        <lower>-1.57</lower>
        <upper>1.57</upper>
      </limit>
    </axis>
  </joint> -->

  <!-- Include the BlueBoat -->
  <include>
    <pose>0 0 0 0 0 0</pose>
    <uri>model://blueboat</uri>
  </include>

  <!-- Include the first Barrage Buoy -->
  <include>
    <pose>-0.5 0 0 0 0 0</pose>
    <uri>model://barrage_buoy</uri>
    <name>barrage_buoy_1</name>
  </include>

  <!-- Fixed Joint connecting BlueBoat and first Barrage Buoy -->
  <joint name="blueboat_to_barragebuoy1_joint" type="fixed">
    <parent>blueboat::base_link</parent> 
    <child>barrage_buoy_1::base_link</child> 
    <pose>0 0 0 0 0 0</pose>
  </joint>

  <!-- Include the second Barrage Buoy -->
  <include>
    <pose>-1.0 0 0 0 0 0</pose>
    <uri>model://barrage_buoy</uri>
    <name>barrage_buoy_2</name>
  </include>

  <!-- Universal Joint connecting first and second Barrage Buoys -->
  <joint name="barragebuoy1_to_barragebuoy2_joint" type="universal">
    <parent>barrage_buoy_1::base_link</parent> 
    <child>barrage_buoy_2::base_link</child> 
    <pose>0 0 0 0 0 0</pose>
    <axis>
      <xyz>0 1 0</xyz>
      <limit>
        <lower>-0.5</lower>
        <upper>0.5</upper>
      </limit>
      <dynamics>
        <damping>0.05</damping>
      </dynamics>
    </axis>
    <axis2>
      <xyz>1 0 0</xyz>
      <limit>
        <lower>-0.5</lower>
        <upper>0.5</upper>
      </limit>
      <dynamics>
        <damping>0.05</damping>
      </dynamics>
    </axis2>
  </joint>

  <!-- Include the third Barrage Buoy -->
  <include>
    <pose>-1.5 0 0 0 0 0</pose>
    <uri>model://barrage_buoy</uri>
    <name>barrage_buoy_3</name>
  </include>

  <!-- Universal Joint connecting second and third Barrage Buoys -->
  <joint name="barragebuoy2_to_barragebuoy3_joint" type="universal">
    <parent>barrage_buoy_2::base_link</parent> 
    <child>barrage_buoy_3::base_link</child> 
    <pose>0 0 0 0 0 0</pose>
    <axis>
      <xyz>0 1 0</xyz>
      <limit>
        <lower>-0.5</lower>
        <upper>0.5</upper>
      </limit>
      <dynamics>
        <damping>0.05</damping>
      </dynamics>
    </axis>
    <axis2>
      <xyz>1 0 0</xyz>
      <limit>
        <lower>-0.5</lower>
        <upper>0.5</upper>
      </limit>
      <dynamics>
        <damping>0.05</damping>
      </dynamics>
    </axis2>
  </joint>

  <!-- Include the fourth Barrage Buoy -->
  <include>
    <pose>-2.0 0 0 0 0 0</pose>
    <uri>model://barrage_buoy</uri>
    <name>barrage_buoy_4</name>
  </include>

  <!-- Universal Joint connecting third and fourth Barrage Buoys -->
  <joint name="barragebuoy3_to_barragebuoy4_joint" type="universal">
    <parent>barrage_buoy_3::base_link</parent> 
    <child>barrage_buoy_4::base_link</child> 
    <pose>0 0 0 0 0 0</pose>
    <axis>
      <xyz>0 1 0</xyz>
      <limit>
        <lower>-0.5</lower>
        <upper>0.5</upper>
      </limit>
      <dynamics>
        <damping>0.05</damping>
      </dynamics>
    </axis>
    <axis2>
      <xyz>1 0 0</xyz>
      <limit>
        <lower>-0.5</lower>
        <upper>0.5</upper>
      </limit>
      <dynamics>
        <damping>0.05</damping>
      </dynamics>
    </axis2>
  </joint>

  <!-- Include the fifth Barrage Buoy -->
  <include>
    <pose>-2.5 0 0 0 0 0</pose>
    <uri>model://barrage_buoy</uri>
    <name>barrage_buoy_5</name>
  </include>

  <!-- Universal Joint connecting fourth and fifth Barrage Buoys -->
  <joint name="barragebuoy4_to_barragebuoy5_joint" type="universal">
    <parent>barrage_buoy_4::base_link</parent> 
    <child>barrage_buoy_5::base_link</child> 
    <pose>0 0 0 0 0 0</pose>
    <axis>
      <xyz>0 1 0</xyz>
      <limit>
        <lower>-0.5</lower>
        <upper>0.5</upper>
      </limit>
      <dynamics>
        <damping>0.05</damping>
      </dynamics>
    </axis>
    <axis2>
      <xyz>1 0 0</xyz>
      <limit>
        <lower>-0.5</lower>
        <upper>0.5</upper>
      </limit>
      <dynamics>
        <damping>0.05</damping>
      </dynamics>
    </axis2>
  </joint>

  <!-- Include the sixth Barrage Buoy -->
  <include>
    <pose>-3.0 0 0 0 0 0</pose>
    <uri>model://barrage_buoy</uri>
    <name>barrage_buoy_6</name>
  </include>

  <!-- Universal Joint connecting fifth and sixth Barrage Buoys -->
  <joint name="barragebuoy5_to_barragebuoy6_joint" type="universal">
    <parent>barrage_buoy_5::base_link</parent> 
    <child>barrage_buoy_6::base_link</child> 
    <pose>0 0 0 0 0 0</pose>
    <axis>
      <xyz>0 1 0</xyz>
      <limit>
        <lower>-0.5</lower>
        <upper>0.5</upper>
      </limit>
      <dynamics>
        <damping>0.05</damping>
      </dynamics>
    </axis>
    <axis2>
      <xyz>1 0 0</xyz>
      <limit>
        <lower>-0.5</lower>
        <upper>0.5</upper>
      </limit>
      <dynamics>
        <damping>0.05</damping>
      </dynamics>
    </axis2>
  </joint>

  <include>
    <pose>-3.0 0 0.0 0 0 0</pose> <!-- Closer to the last buoy and less deep -->
    <uri>model://bluerov2_heavy</uri>
    <name>bluerov2_heavy</name>
  </include>

  <!-- Universal Joint connecting the last Barrage Buoy to BlueROV2 -->
  <joint name="barragebuoy6_to_bluerov2_joint" type="universal">
    <parent>barrage_buoy_6::base_link</parent> 
    <child>bluerov2_heavy::base_link</child> 
    <pose>0 0 0 0 0 0</pose> <!-- Adjusted to be close and aligned -->
    <axis>
      <xyz>0 1 0</xyz>
      <limit>
        <lower>-0.5</lower>
        <upper>0.5</upper>
      </limit>
      <dynamics>
        <damping>0.05</damping>
      </dynamics>
    </axis>
    <axis2>
      <xyz>1 0 0</xyz>
      <limit>
        <lower>-0.5</lower>
        <upper>0.5</upper>
      </limit>
      <dynamics>
        <damping>0.05</damping>
      </dynamics>
    </axis2>
  </joint>



<!-- BlueROV2 -->
<!-- <include>
  <pose>-6 0 0 0 0 0</pose>
  <uri>model://bluerov2_heavy</uri>
</include> -->

<!-- <joint name="bluerov2_to_barrage_joint" type="revolute">
  <parent>barrage::attachment_link_2</parent>
  <child>bluerov2_heavy::base_link</child>

  <pose>0 0 0 0 0 0</pose>

  <axis>
    <xyz>0 1 0</xyz>
    <limit>
      <lower>-1.57</lower>
      <upper>1.57</upper>
    </limit>
  </axis>
</joint> -->







  </world>
</sdf>